[17/03/2018 22:56] ERROR red load_cogs 573: ffmpeg isn't installed.
Consult the guide for your operating system and do ALL the steps in order.
https://twentysix26.github.io/Red-Docs/
Traceback (most recent call last):
  File "red.py", line 570, in load_cogs
    owner_cog._load_cog(extension)
  File "C:\Users\waz78\Documents\Discord stuff\Red-DiscordBot\cogs\owner.py", line 948, in _load_cog
    self.bot.load_extension(mod_obj.__name__)
  File "lib\discord\ext\commands\bot.py", line 738, in load_extension
    lib.setup(self)
  File "C:\Users\waz78\Documents\Discord stuff\Red-DiscordBot\cogs\audio.py", line 2372, in setup
    "".format(msg))
RuntimeError: ffmpeg isn't installed.
Consult the guide for your operating system and do ALL the steps in order.
https://twentysix26.github.io/Red-Docs/

[17/03/2018 23:13] ERROR owner load 74: ffmpeg isn't installed.
Consult the guide for your operating system and do ALL the steps in order.
https://twentysix26.github.io/Red-Docs/
Traceback (most recent call last):
  File "C:\Users\waz78\Documents\Discord stuff\Red-DiscordBot\cogs\owner.py", line 65, in load
    self._load_cog(module)
  File "C:\Users\waz78\Documents\Discord stuff\Red-DiscordBot\cogs\owner.py", line 948, in _load_cog
    self.bot.load_extension(mod_obj.__name__)
  File "lib\discord\ext\commands\bot.py", line 738, in load_extension
    lib.setup(self)
  File "C:\Users\waz78\Documents\Discord stuff\Red-DiscordBot\cogs\audio.py", line 2372, in setup
    "".format(msg))
RuntimeError: ffmpeg isn't installed.
Consult the guide for your operating system and do ALL the steps in order.
https://twentysix26.github.io/Red-Docs/

[18/03/2018 00:05] ERROR red on_command_error 369: Exception in command 'catfact'
Traceback (most recent call last):
  File "lib\discord\ext\commands\core.py", line 50, in wrapped
    ret = yield from coro(*args, **kwargs)
  File "C:\Users\waz78\Documents\Discord stuff\Red-DiscordBot\cogs\catfact.py", line 30, in _catfact
    for fact in json.loads(await response.text())["facts"]:
  File "C:\Users\waz78\AppData\Local\Programs\Python\Python36-32\lib\json\__init__.py", line 354, in loads
    return _default_decoder.decode(s)
  File "C:\Users\waz78\AppData\Local\Programs\Python\Python36-32\lib\json\decoder.py", line 339, in decode
    obj, end = self.raw_decode(s, idx=_w(s, 0).end())
  File "C:\Users\waz78\AppData\Local\Programs\Python\Python36-32\lib\json\decoder.py", line 357, in raw_decode
    raise JSONDecodeError("Expecting value", s, err.value) from None
json.decoder.JSONDecodeError: Expecting value: line 1 column 1 (char 0)
[18/03/2018 00:06] ERROR red on_command_error 369: Exception in command 'catfact'
Traceback (most recent call last):
  File "lib\discord\ext\commands\core.py", line 50, in wrapped
    ret = yield from coro(*args, **kwargs)
  File "C:\Users\waz78\Documents\Discord stuff\Red-DiscordBot\cogs\catfact.py", line 30, in _catfact
    for fact in json.loads(await response.text())["facts"]:
  File "C:\Users\waz78\AppData\Local\Programs\Python\Python36-32\lib\json\__init__.py", line 354, in loads
    return _default_decoder.decode(s)
  File "C:\Users\waz78\AppData\Local\Programs\Python\Python36-32\lib\json\decoder.py", line 339, in decode
    obj, end = self.raw_decode(s, idx=_w(s, 0).end())
  File "C:\Users\waz78\AppData\Local\Programs\Python\Python36-32\lib\json\decoder.py", line 357, in raw_decode
    raise JSONDecodeError("Expecting value", s, err.value) from None
json.decoder.JSONDecodeError: Expecting value: line 1 column 1 (char 0)
[18/03/2018 11:06] ERROR red on_command_error 369: Exception in command 'p role allow'
Traceback (most recent call last):
  File "lib\discord\ext\commands\core.py", line 50, in wrapped
    ret = yield from coro(*args, **kwargs)
  File "C:\Users\waz78\Documents\Discord stuff\Red-DiscordBot\cogs\permissions.py", line 758, in role_allow
    role = self._get_role(server.roles, role)
  File "C:\Users\waz78\Documents\Discord stuff\Red-DiscordBot\cogs\permissions.py", line 238, in _get_role
    raise RoleNotFound(roles[0].server, role_string)
  File "lib\discord\ext\commands\errors.py", line 46, in __init__
    m = message.replace('@everyone', '@\u200beveryone').replace('@here', '@\u200bhere')
AttributeError: 'Server' object has no attribute 'replace'
[18/03/2018 11:42] ERROR red on_command_error 369: Exception in command 'catfact'
Traceback (most recent call last):
  File "lib\discord\ext\commands\core.py", line 50, in wrapped
    ret = yield from coro(*args, **kwargs)
  File "C:\Users\waz78\Documents\Discord stuff\Red-DiscordBot\cogs\catfact.py", line 30, in _catfact
    for fact in json.loads(await response.text())["facts"]:
  File "C:\Users\waz78\AppData\Local\Programs\Python\Python36-32\lib\json\__init__.py", line 354, in loads
    return _default_decoder.decode(s)
  File "C:\Users\waz78\AppData\Local\Programs\Python\Python36-32\lib\json\decoder.py", line 339, in decode
    obj, end = self.raw_decode(s, idx=_w(s, 0).end())
  File "C:\Users\waz78\AppData\Local\Programs\Python\Python36-32\lib\json\decoder.py", line 357, in raw_decode
    raise JSONDecodeError("Expecting value", s, err.value) from None
json.decoder.JSONDecodeError: Expecting value: line 1 column 1 (char 0)
[18/03/2018 11:42] ERROR red on_command_error 369: Exception in command 'catfact'
Traceback (most recent call last):
  File "lib\discord\ext\commands\core.py", line 50, in wrapped
    ret = yield from coro(*args, **kwargs)
  File "C:\Users\waz78\Documents\Discord stuff\Red-DiscordBot\cogs\catfact.py", line 30, in _catfact
    for fact in json.loads(await response.text())["facts"]:
  File "C:\Users\waz78\AppData\Local\Programs\Python\Python36-32\lib\json\__init__.py", line 354, in loads
    return _default_decoder.decode(s)
  File "C:\Users\waz78\AppData\Local\Programs\Python\Python36-32\lib\json\decoder.py", line 339, in decode
    obj, end = self.raw_decode(s, idx=_w(s, 0).end())
  File "C:\Users\waz78\AppData\Local\Programs\Python\Python36-32\lib\json\decoder.py", line 357, in raw_decode
    raise JSONDecodeError("Expecting value", s, err.value) from None
json.decoder.JSONDecodeError: Expecting value: line 1 column 1 (char 0)
[18/03/2018 11:56] ERROR red on_command_error 369: Exception in command 'catfact'
Traceback (most recent call last):
  File "lib\discord\ext\commands\core.py", line 50, in wrapped
    ret = yield from coro(*args, **kwargs)
  File "C:\Users\waz78\Documents\Discord stuff\Red-DiscordBot\cogs\catfact.py", line 30, in _catfact
    for fact in json.loads(await response.text())["facts"]:
  File "C:\Users\waz78\AppData\Local\Programs\Python\Python36-32\lib\json\__init__.py", line 354, in loads
    return _default_decoder.decode(s)
  File "C:\Users\waz78\AppData\Local\Programs\Python\Python36-32\lib\json\decoder.py", line 339, in decode
    obj, end = self.raw_decode(s, idx=_w(s, 0).end())
  File "C:\Users\waz78\AppData\Local\Programs\Python\Python36-32\lib\json\decoder.py", line 357, in raw_decode
    raise JSONDecodeError("Expecting value", s, err.value) from None
json.decoder.JSONDecodeError: Expecting value: line 1 column 1 (char 0)
[18/03/2018 19:19] ERROR red on_command_error 369: Exception in command 'catfact'
Traceback (most recent call last):
  File "lib\discord\ext\commands\core.py", line 50, in wrapped
    ret = yield from coro(*args, **kwargs)
  File "C:\Users\waz78\Documents\Discord stuff\Red-DiscordBot\cogs\catfact.py", line 30, in _catfact
    for fact in json.loads(await response.text())["facts"]:
  File "C:\Users\waz78\AppData\Local\Programs\Python\Python36-32\lib\json\__init__.py", line 354, in loads
    return _default_decoder.decode(s)
  File "C:\Users\waz78\AppData\Local\Programs\Python\Python36-32\lib\json\decoder.py", line 339, in decode
    obj, end = self.raw_decode(s, idx=_w(s, 0).end())
  File "C:\Users\waz78\AppData\Local\Programs\Python\Python36-32\lib\json\decoder.py", line 357, in raw_decode
    raise JSONDecodeError("Expecting value", s, err.value) from None
json.decoder.JSONDecodeError: Expecting value: line 1 column 1 (char 0)
[18/03/2018 19:24] ERROR red on_command_error 369: Exception in command 'catfact'
Traceback (most recent call last):
  File "lib\discord\ext\commands\core.py", line 50, in wrapped
    ret = yield from coro(*args, **kwargs)
  File "C:\Users\waz78\Documents\Discord stuff\Red-DiscordBot\cogs\catfact.py", line 30, in _catfact
    for fact in json.loads(await response.text())["facts"]:
  File "C:\Users\waz78\AppData\Local\Programs\Python\Python36-32\lib\json\__init__.py", line 354, in loads
    return _default_decoder.decode(s)
  File "C:\Users\waz78\AppData\Local\Programs\Python\Python36-32\lib\json\decoder.py", line 339, in decode
    obj, end = self.raw_decode(s, idx=_w(s, 0).end())
  File "C:\Users\waz78\AppData\Local\Programs\Python\Python36-32\lib\json\decoder.py", line 357, in raw_decode
    raise JSONDecodeError("Expecting value", s, err.value) from None
json.decoder.JSONDecodeError: Expecting value: line 1 column 1 (char 0)
[18/03/2018 19:24] ERROR red on_command_error 369: Exception in command 'catfact'
Traceback (most recent call last):
  File "lib\discord\ext\commands\core.py", line 50, in wrapped
    ret = yield from coro(*args, **kwargs)
  File "C:\Users\waz78\Documents\Discord stuff\Red-DiscordBot\cogs\catfact.py", line 30, in _catfact
    for fact in json.loads(await response.text())["facts"]:
  File "C:\Users\waz78\AppData\Local\Programs\Python\Python36-32\lib\json\__init__.py", line 354, in loads
    return _default_decoder.decode(s)
  File "C:\Users\waz78\AppData\Local\Programs\Python\Python36-32\lib\json\decoder.py", line 339, in decode
    obj, end = self.raw_decode(s, idx=_w(s, 0).end())
  File "C:\Users\waz78\AppData\Local\Programs\Python\Python36-32\lib\json\decoder.py", line 357, in raw_decode
    raise JSONDecodeError("Expecting value", s, err.value) from None
json.decoder.JSONDecodeError: Expecting value: line 1 column 1 (char 0)
[18/03/2018 19:59] ERROR red on_command_error 369: Exception in command 'catfact'
Traceback (most recent call last):
  File "lib\discord\ext\commands\core.py", line 50, in wrapped
    ret = yield from coro(*args, **kwargs)
  File "C:\Users\waz78\Documents\Discord stuff\Red-DiscordBot\cogs\catfact.py", line 30, in _catfact
    for fact in json.loads(await response.text())["facts"]:
  File "C:\Users\waz78\AppData\Local\Programs\Python\Python36-32\lib\json\__init__.py", line 354, in loads
    return _default_decoder.decode(s)
  File "C:\Users\waz78\AppData\Local\Programs\Python\Python36-32\lib\json\decoder.py", line 339, in decode
    obj, end = self.raw_decode(s, idx=_w(s, 0).end())
  File "C:\Users\waz78\AppData\Local\Programs\Python\Python36-32\lib\json\decoder.py", line 357, in raw_decode
    raise JSONDecodeError("Expecting value", s, err.value) from None
json.decoder.JSONDecodeError: Expecting value: line 1 column 1 (char 0)
[18/03/2018 22:18] ERROR red on_command_error 369: Exception in command 'skip'
Traceback (most recent call last):
  File "lib\discord\ext\commands\core.py", line 50, in wrapped
    ret = yield from coro(*args, **kwargs)
  File "C:\Users\waz78\Documents\Discord stuff\Red-DiscordBot\cogs\audio.py", line 1906, in skip
    for m in vchan.voice_members)
  File "C:\Users\waz78\Documents\Discord stuff\Red-DiscordBot\cogs\audio.py", line 1906, in <genexpr>
    for m in vchan.voice_members)
  File "C:\Users\waz78\Documents\Discord stuff\Red-DiscordBot\cogs\audio.py", line 1929, in can_instaskip
    if not self.get_server_settings(server)["VOTE_ENABLED"]:
  File "C:\Users\waz78\Documents\Discord stuff\Red-DiscordBot\cogs\audio.py", line 2104, in get_server_settings
    self.save_settings()
  File "C:\Users\waz78\Documents\Discord stuff\Red-DiscordBot\cogs\audio.py", line 2242, in save_settings
    dataIO.save_json('data/audio/settings.json', self.settings)
  File "C:\Users\waz78\Documents\Discord stuff\Red-DiscordBot\cogs\utils\dataIO.py", line 27, in save_json
    os.replace(tmp_file, filename)
PermissionError: [WinError 5] Access is denied: 'data/audio/settings-5518.tmp' -> 'data/audio/settings.json'
[18/03/2018 23:03] ERROR red load_cogs 573: ('inconsistent use of tabs and spaces in indentation', ('C:\\Users\\waz78\\Documents\\Discord stuff\\Red-DiscordBot\\cogs\\economy.py', 565, 52, '\t@commands.command(pass_context=True, no_pm=True)\t\t\n'))
Traceback (most recent call last):
  File "C:\Users\waz78\Documents\Discord stuff\Red-DiscordBot\cogs\owner.py", line 946, in _load_cog
    mod_obj = importlib.import_module(cogname)
  File "C:\Users\waz78\AppData\Local\Programs\Python\Python36-32\lib\importlib\__init__.py", line 126, in import_module
    return _bootstrap._gcd_import(name[level:], package, level)
  File "<frozen importlib._bootstrap>", line 994, in _gcd_import
  File "<frozen importlib._bootstrap>", line 971, in _find_and_load
  File "<frozen importlib._bootstrap>", line 955, in _find_and_load_unlocked
  File "<frozen importlib._bootstrap>", line 665, in _load_unlocked
  File "<frozen importlib._bootstrap_external>", line 674, in exec_module
  File "<frozen importlib._bootstrap_external>", line 781, in get_code
  File "<frozen importlib._bootstrap_external>", line 741, in source_to_code
  File "<frozen importlib._bootstrap>", line 219, in _call_with_frames_removed
  File "C:\Users\waz78\Documents\Discord stuff\Red-DiscordBot\cogs\economy.py", line 565
    @commands.command(pass_context=True, no_pm=True)
                                                    	^
TabError: inconsistent use of tabs and spaces in indentation

During handling of the above exception, another exception occurred:

Traceback (most recent call last):
  File "C:\Users\waz78\Documents\Discord stuff\Red-DiscordBot\red.py", line 570, in load_cogs
    owner_cog._load_cog(extension)
  File "C:\Users\waz78\Documents\Discord stuff\Red-DiscordBot\cogs\owner.py", line 950, in _load_cog
    raise CogLoadError(*e.args)
cogs.owner.CogLoadError: ('inconsistent use of tabs and spaces in indentation', ('C:\\Users\\waz78\\Documents\\Discord stuff\\Red-DiscordBot\\cogs\\economy.py', 565, 52, '\t@commands.command(pass_context=True, no_pm=True)\t\t\n'))
[18/03/2018 23:10] ERROR owner load 69: ('inconsistent use of tabs and spaces in indentation', ('C:\\Users\\waz78\\Documents\\Discord stuff\\Red-DiscordBot\\cogs\\economy.py', 571, 38, '\t\tbid = self.bank.get_balance(author)\n'))
Traceback (most recent call last):
  File "C:\Users\waz78\Documents\Discord stuff\Red-DiscordBot\cogs\owner.py", line 946, in _load_cog
    mod_obj = importlib.import_module(cogname)
  File "C:\Users\waz78\AppData\Local\Programs\Python\Python36-32\lib\importlib\__init__.py", line 126, in import_module
    return _bootstrap._gcd_import(name[level:], package, level)
  File "<frozen importlib._bootstrap>", line 994, in _gcd_import
  File "<frozen importlib._bootstrap>", line 971, in _find_and_load
  File "<frozen importlib._bootstrap>", line 955, in _find_and_load_unlocked
  File "<frozen importlib._bootstrap>", line 665, in _load_unlocked
  File "<frozen importlib._bootstrap_external>", line 674, in exec_module
  File "<frozen importlib._bootstrap_external>", line 781, in get_code
  File "<frozen importlib._bootstrap_external>", line 741, in source_to_code
  File "<frozen importlib._bootstrap>", line 219, in _call_with_frames_removed
  File "C:\Users\waz78\Documents\Discord stuff\Red-DiscordBot\cogs\economy.py", line 571
    bid = self.bank.get_balance(author)
                                      ^
TabError: inconsistent use of tabs and spaces in indentation

During handling of the above exception, another exception occurred:

Traceback (most recent call last):
  File "C:\Users\waz78\Documents\Discord stuff\Red-DiscordBot\cogs\owner.py", line 65, in load
    self._load_cog(module)
  File "C:\Users\waz78\Documents\Discord stuff\Red-DiscordBot\cogs\owner.py", line 950, in _load_cog
    raise CogLoadError(*e.args)
cogs.owner.CogLoadError: ('inconsistent use of tabs and spaces in indentation', ('C:\\Users\\waz78\\Documents\\Discord stuff\\Red-DiscordBot\\cogs\\economy.py', 571, 38, '\t\tbid = self.bank.get_balance(author)\n'))
[18/03/2018 23:11] ERROR owner load 69: ('inconsistent use of tabs and spaces in indentation', ('C:\\Users\\waz78\\Documents\\Discord stuff\\Red-DiscordBot\\cogs\\economy.py', 571, 37, '\tbid = self.bank.get_balance(author)\n'))
Traceback (most recent call last):
  File "C:\Users\waz78\Documents\Discord stuff\Red-DiscordBot\cogs\owner.py", line 946, in _load_cog
    mod_obj = importlib.import_module(cogname)
  File "C:\Users\waz78\AppData\Local\Programs\Python\Python36-32\lib\importlib\__init__.py", line 126, in import_module
    return _bootstrap._gcd_import(name[level:], package, level)
  File "<frozen importlib._bootstrap>", line 994, in _gcd_import
  File "<frozen importlib._bootstrap>", line 971, in _find_and_load
  File "<frozen importlib._bootstrap>", line 955, in _find_and_load_unlocked
  File "<frozen importlib._bootstrap>", line 665, in _load_unlocked
  File "<frozen importlib._bootstrap_external>", line 674, in exec_module
  File "<frozen importlib._bootstrap_external>", line 781, in get_code
  File "<frozen importlib._bootstrap_external>", line 741, in source_to_code
  File "<frozen importlib._bootstrap>", line 219, in _call_with_frames_removed
  File "C:\Users\waz78\Documents\Discord stuff\Red-DiscordBot\cogs\economy.py", line 571
    bid = self.bank.get_balance(author)
                                      ^
TabError: inconsistent use of tabs and spaces in indentation

During handling of the above exception, another exception occurred:

Traceback (most recent call last):
  File "C:\Users\waz78\Documents\Discord stuff\Red-DiscordBot\cogs\owner.py", line 65, in load
    self._load_cog(module)
  File "C:\Users\waz78\Documents\Discord stuff\Red-DiscordBot\cogs\owner.py", line 950, in _load_cog
    raise CogLoadError(*e.args)
cogs.owner.CogLoadError: ('inconsistent use of tabs and spaces in indentation', ('C:\\Users\\waz78\\Documents\\Discord stuff\\Red-DiscordBot\\cogs\\economy.py', 571, 37, '\tbid = self.bank.get_balance(author)\n'))
[19/03/2018 08:55] ERROR red on_command_error 369: Exception in command 'catfact'
Traceback (most recent call last):
  File "lib\discord\ext\commands\core.py", line 50, in wrapped
    ret = yield from coro(*args, **kwargs)
  File "C:\Users\waz78\Documents\Discord stuff\Red-DiscordBot\cogs\catfact.py", line 30, in _catfact
    for fact in json.loads(await response.text())["facts"]:
  File "C:\Users\waz78\AppData\Local\Programs\Python\Python36-32\lib\json\__init__.py", line 354, in loads
    return _default_decoder.decode(s)
  File "C:\Users\waz78\AppData\Local\Programs\Python\Python36-32\lib\json\decoder.py", line 339, in decode
    obj, end = self.raw_decode(s, idx=_w(s, 0).end())
  File "C:\Users\waz78\AppData\Local\Programs\Python\Python36-32\lib\json\decoder.py", line 357, in raw_decode
    raise JSONDecodeError("Expecting value", s, err.value) from None
json.decoder.JSONDecodeError: Expecting value: line 1 column 1 (char 0)
[20/03/2018 17:20] ERROR red on_command_error 369: Exception in command 'catfact'
Traceback (most recent call last):
  File "lib\discord\ext\commands\core.py", line 50, in wrapped
    ret = yield from coro(*args, **kwargs)
  File "C:\Users\waz78\Documents\Discord stuff\Red-DiscordBot\cogs\catfact.py", line 30, in _catfact
    for fact in json.loads(await response.text())["facts"]:
  File "C:\Users\waz78\AppData\Local\Programs\Python\Python36-32\lib\json\__init__.py", line 354, in loads
    return _default_decoder.decode(s)
  File "C:\Users\waz78\AppData\Local\Programs\Python\Python36-32\lib\json\decoder.py", line 339, in decode
    obj, end = self.raw_decode(s, idx=_w(s, 0).end())
  File "C:\Users\waz78\AppData\Local\Programs\Python\Python36-32\lib\json\decoder.py", line 357, in raw_decode
    raise JSONDecodeError("Expecting value", s, err.value) from None
json.decoder.JSONDecodeError: Expecting value: line 1 column 1 (char 0)
[20/03/2018 17:20] ERROR red on_command_error 369: Exception in command 'catfact'
Traceback (most recent call last):
  File "lib\discord\ext\commands\core.py", line 50, in wrapped
    ret = yield from coro(*args, **kwargs)
  File "C:\Users\waz78\Documents\Discord stuff\Red-DiscordBot\cogs\catfact.py", line 30, in _catfact
    for fact in json.loads(await response.text())["facts"]:
  File "C:\Users\waz78\AppData\Local\Programs\Python\Python36-32\lib\json\__init__.py", line 354, in loads
    return _default_decoder.decode(s)
  File "C:\Users\waz78\AppData\Local\Programs\Python\Python36-32\lib\json\decoder.py", line 339, in decode
    obj, end = self.raw_decode(s, idx=_w(s, 0).end())
  File "C:\Users\waz78\AppData\Local\Programs\Python\Python36-32\lib\json\decoder.py", line 357, in raw_decode
    raise JSONDecodeError("Expecting value", s, err.value) from None
json.decoder.JSONDecodeError: Expecting value: line 1 column 1 (char 0)
[21/03/2018 11:51] INFO economy transfer 352: Sheepdog McFry(126676932283596800) transferred 1000 credits to Baloo(425586687465488385)
[23/03/2018 18:43] INFO economy transfer 352: Sheepdog McFry(126676932283596800) transferred 1000 credits to Fluffy/Angry Potato(338772156672507904)
[23/03/2018 18:43] INFO economy transfer 352: Sheepdog McFry(126676932283596800) transferred 1000 credits to LifeDeath(401878404749590529)
[26/03/2018 21:14] INFO economy transfer 352: Sheepdog McFry(126676932283596800) transferred 6000 credits to rafthemaster(388681687241981955)
[26/03/2018 21:14] INFO economy transfer 352: Sheepdog McFry(126676932283596800) transferred 6000 credits to Starshiptrooper(414132578241478656)
[27/03/2018 16:58] INFO economy transfer 352: Sheepdog McFry(126676932283596800) transferred 5000 credits to LordBob(424676840180023307)
[27/03/2018 20:15] ERROR red on_command_error 369: Exception in command 'catfact'
Traceback (most recent call last):
  File "lib\discord\ext\commands\core.py", line 50, in wrapped
    ret = yield from coro(*args, **kwargs)
  File "C:\Users\waz78\Documents\Discord stuff\Red-DiscordBot\cogs\catfact.py", line 30, in _catfact
    for fact in json.loads(await response.text())["facts"]:
  File "C:\Users\waz78\AppData\Local\Programs\Python\Python36-32\lib\json\__init__.py", line 354, in loads
    return _default_decoder.decode(s)
  File "C:\Users\waz78\AppData\Local\Programs\Python\Python36-32\lib\json\decoder.py", line 339, in decode
    obj, end = self.raw_decode(s, idx=_w(s, 0).end())
  File "C:\Users\waz78\AppData\Local\Programs\Python\Python36-32\lib\json\decoder.py", line 357, in raw_decode
    raise JSONDecodeError("Expecting value", s, err.value) from None
json.decoder.JSONDecodeError: Expecting value: line 1 column 1 (char 0)
[27/03/2018 20:18] ERROR red on_command_error 369: Exception in command 'slotall'
Traceback (most recent call last):
  File "lib\discord\ext\commands\core.py", line 50, in wrapped
    ret = yield from coro(*args, **kwargs)
  File "C:\Users\waz78\Documents\Discord stuff\Red-DiscordBot\cogs\economy.py", line 579, in slotall
    if not valid_bid:
NameError: name 'valid_bid' is not defined
[27/03/2018 20:18] ERROR red on_command_error 369: Exception in command 'slotall'
Traceback (most recent call last):
  File "lib\discord\ext\commands\core.py", line 50, in wrapped
    ret = yield from coro(*args, **kwargs)
  File "C:\Users\waz78\Documents\Discord stuff\Red-DiscordBot\cogs\economy.py", line 579, in slotall
    if not valid_bid:
NameError: name 'valid_bid' is not defined
[27/03/2018 22:44] ERROR red on_command_error 369: Exception in command 'catfact'
Traceback (most recent call last):
  File "lib\discord\ext\commands\core.py", line 50, in wrapped
    ret = yield from coro(*args, **kwargs)
  File "C:\Users\waz78\Documents\Discord stuff\Red-DiscordBot\cogs\catfact.py", line 30, in _catfact
    for fact in json.loads(await response.text())["facts"]:
  File "C:\Users\waz78\AppData\Local\Programs\Python\Python36-32\lib\json\__init__.py", line 354, in loads
    return _default_decoder.decode(s)
  File "C:\Users\waz78\AppData\Local\Programs\Python\Python36-32\lib\json\decoder.py", line 339, in decode
    obj, end = self.raw_decode(s, idx=_w(s, 0).end())
  File "C:\Users\waz78\AppData\Local\Programs\Python\Python36-32\lib\json\decoder.py", line 357, in raw_decode
    raise JSONDecodeError("Expecting value", s, err.value) from None
json.decoder.JSONDecodeError: Expecting value: line 1 column 1 (char 0)
[27/03/2018 22:48] ERROR red on_command_error 369: Exception in command 'catfact'
Traceback (most recent call last):
  File "lib\discord\ext\commands\core.py", line 50, in wrapped
    ret = yield from coro(*args, **kwargs)
  File "C:\Users\waz78\Documents\Discord stuff\Red-DiscordBot\cogs\catfact.py", line 30, in _catfact
    for fact in json.loads(await response.text())["facts"]:
KeyError: 'facts'
[27/03/2018 22:49] ERROR red on_command_error 369: Exception in command 'catfact'
Traceback (most recent call last):
  File "lib\discord\ext\commands\core.py", line 50, in wrapped
    ret = yield from coro(*args, **kwargs)
  File "C:\Users\waz78\Documents\Discord stuff\Red-DiscordBot\cogs\catfact.py", line 31, in _catfact
    await self.bot.say(fact)
  File "lib\discord\ext\commands\bot.py", line 309, in _augmented_msg
    msg = yield from coro
  File "C:\Users\waz78\Documents\Discord stuff\Red-DiscordBot\red.py", line 92, in send_message
    return await super().send_message(*args, **kwargs)
  File "lib\discord\client.py", line 1151, in send_message
    data = yield from self.http.send_message(channel_id, content, guild_id=guild_id, tts=tts, embed=embed)
  File "lib\discord\http.py", line 200, in request
    raise HTTPException(r, data)
discord.errors.HTTPException: BAD REQUEST (status code: 400): Cannot send an empty message
[27/03/2018 23:00] ERROR red on_command_error 369: Exception in command 'catfact'
Traceback (most recent call last):
  File "lib\discord\ext\commands\core.py", line 50, in wrapped
    ret = yield from coro(*args, **kwargs)
  File "C:\Users\waz78\Documents\Discord stuff\Red-DiscordBot\cogs\catfact.py", line 31, in _catfact
    await self.bot.say(fact)
  File "lib\discord\ext\commands\bot.py", line 309, in _augmented_msg
    msg = yield from coro
  File "C:\Users\waz78\Documents\Discord stuff\Red-DiscordBot\red.py", line 92, in send_message
    return await super().send_message(*args, **kwargs)
  File "lib\discord\client.py", line 1151, in send_message
    data = yield from self.http.send_message(channel_id, content, guild_id=guild_id, tts=tts, embed=embed)
  File "lib\discord\http.py", line 200, in request
    raise HTTPException(r, data)
discord.errors.HTTPException: BAD REQUEST (status code: 400): Cannot send an empty message
[27/03/2018 23:02] ERROR red on_command_error 369: Exception in command 'catfact'
Traceback (most recent call last):
  File "lib\discord\ext\commands\core.py", line 50, in wrapped
    ret = yield from coro(*args, **kwargs)
  File "C:\Users\waz78\Documents\Discord stuff\Red-DiscordBot\cogs\catfact.py", line 30, in _catfact
    await self.bot.say(json.loads(fact))
NameError: name 'fact' is not defined
[27/03/2018 23:06] ERROR red on_command_error 369: Exception in command 'catfact'
Traceback (most recent call last):
  File "lib\discord\ext\commands\core.py", line 50, in wrapped
    ret = yield from coro(*args, **kwargs)
  File "C:\Users\waz78\Documents\Discord stuff\Red-DiscordBot\cogs\catfact.py", line 30, in _catfact
    await self.bot.say(response.json["fact"])
TypeError: 'method' object is not subscriptable
[27/03/2018 23:08] ERROR red on_command_error 369: Exception in command 'catfact'
Traceback (most recent call last):
  File "lib\discord\ext\commands\core.py", line 50, in wrapped
    ret = yield from coro(*args, **kwargs)
  File "C:\Users\waz78\Documents\Discord stuff\Red-DiscordBot\cogs\catfact.py", line 30, in _catfact
    await self.bot.say(response.json(["fact"]))
TypeError: json() takes 1 positional argument but 2 were given
[27/03/2018 23:09] ERROR red on_command_error 369: Exception in command 'catfact'
Traceback (most recent call last):
  File "lib\discord\ext\commands\core.py", line 50, in wrapped
    ret = yield from coro(*args, **kwargs)
  File "C:\Users\waz78\Documents\Discord stuff\Red-DiscordBot\cogs\catfact.py", line 30, in _catfact
    await self.bot.say(response.json()["fact"])
TypeError: 'generator' object is not subscriptable
[27/03/2018 23:09] ERROR red on_command_error 369: Exception in command 'catfact'
Traceback (most recent call last):
  File "lib\discord\ext\commands\core.py", line 50, in wrapped
    ret = yield from coro(*args, **kwargs)
  File "C:\Users\waz78\Documents\Discord stuff\Red-DiscordBot\cogs\catfact.py", line 30, in _catfact
    await self.bot.say(response.json()["fact"])
TypeError: 'generator' object is not subscriptable
[27/03/2018 23:14] ERROR red on_command_error 369: Exception in command 'catfact'
Traceback (most recent call last):
  File "lib\discord\ext\commands\core.py", line 50, in wrapped
    ret = yield from coro(*args, **kwargs)
  File "C:\Users\waz78\Documents\Discord stuff\Red-DiscordBot\cogs\catfact.py", line 25, in _catfact
    async with session.get(self.url) as response:
NameError: name 'session' is not defined
[27/03/2018 23:16] ERROR red load_cogs 573: ('inconsistent use of tabs and spaces in indentation', ('C:\\Users\\waz78\\Documents\\Discord stuff\\Red-DiscordBot\\cogs\\catfact.py', 26, 32, '\t\t\tdata = await response.json()\n'))
Traceback (most recent call last):
  File "C:\Users\waz78\Documents\Discord stuff\Red-DiscordBot\cogs\owner.py", line 946, in _load_cog
    mod_obj = importlib.import_module(cogname)
  File "C:\Users\waz78\AppData\Local\Programs\Python\Python36-32\lib\importlib\__init__.py", line 126, in import_module
    return _bootstrap._gcd_import(name[level:], package, level)
  File "<frozen importlib._bootstrap>", line 994, in _gcd_import
  File "<frozen importlib._bootstrap>", line 971, in _find_and_load
  File "<frozen importlib._bootstrap>", line 955, in _find_and_load_unlocked
  File "<frozen importlib._bootstrap>", line 665, in _load_unlocked
  File "<frozen importlib._bootstrap_external>", line 674, in exec_module
  File "<frozen importlib._bootstrap_external>", line 781, in get_code
  File "<frozen importlib._bootstrap_external>", line 741, in source_to_code
  File "<frozen importlib._bootstrap>", line 219, in _call_with_frames_removed
  File "C:\Users\waz78\Documents\Discord stuff\Red-DiscordBot\cogs\catfact.py", line 26
    data = await response.json()
                               ^
TabError: inconsistent use of tabs and spaces in indentation

During handling of the above exception, another exception occurred:

Traceback (most recent call last):
  File "C:\Users\waz78\Documents\Discord stuff\Red-DiscordBot\red.py", line 570, in load_cogs
    owner_cog._load_cog(extension)
  File "C:\Users\waz78\Documents\Discord stuff\Red-DiscordBot\cogs\owner.py", line 950, in _load_cog
    raise CogLoadError(*e.args)
cogs.owner.CogLoadError: ('inconsistent use of tabs and spaces in indentation', ('C:\\Users\\waz78\\Documents\\Discord stuff\\Red-DiscordBot\\cogs\\catfact.py', 26, 32, '\t\t\tdata = await response.json()\n'))
[27/03/2018 23:24] ERROR red on_command_error 369: Exception in command 'catfact'
Traceback (most recent call last):
  File "lib\discord\ext\commands\core.py", line 50, in wrapped
    ret = yield from coro(*args, **kwargs)
  File "C:\Users\waz78\Documents\Discord stuff\Red-DiscordBot\cogs\catfact.py", line 26, in _catfact
    await self.bot.say(await response.json()['fact'])
TypeError: 'generator' object is not subscriptable
